<?xml version="1.0" encoding="utf-8"?>

<robot xmlns:xacro="http://wiki.ros.org/xacro">
  <link
    name="base_link">
    <inertial>
      <origin
        xyz="-0.0146959562730705 -1.31808177654722E-09 0.0738790283475741"
        rpy="0 0 0" />
      <mass
        value="5.31276956078926" />
      <inertia
        ixx="0.0254280679798273"
        ixy="-3.83756468568407E-10"
        ixz="-0.00246652568977196"
        iyy="0.0327484488605481"
        iyz="-4.23043782522762E-10"
        izz="0.0305803894465856" />
    </inertial>
    <visual>
      <origin
        xyz="0 0 0"
        rpy="0 0 0" />
      <geometry>
        <mesh
          filename="package://m6r_description/meshes/m6r_0110/base_link.STL" />
      </geometry>
      <material
        name="">
        <color
          rgba="0.894117647058823 0.894117647058823 0.894117647058823 1" />
      </material>
    </visual>
    <collision>
      <origin
        xyz="0 0 0"
        rpy="0 0 0" />
      <geometry>
        <mesh
          filename="package://m6r_description/meshes/m6r_0110/base_link.STL" />
      </geometry>
    </collision>
  </link>
  <link
    name="waist_link">
    <inertial>
      <origin
        xyz="0.0139701613082039 -0.015936284472385 0.132965338967223"
        rpy="0 0 0" />
      <mass
        value="13.4868898164828" />
      <inertia
        ixx="0.103115065826466"
        ixy="-0.0027942922654768"
        ixz="-0.0175187461405487"
        iyy="0.154263710369968"
        iyz="0.00418239915297628"
        izz="0.150904232632326" />
    </inertial>
    <visual>
      <origin
        xyz="0 0 0"
        rpy="0 0 0" />
      <geometry>
        <mesh
          filename="package://m6r_description/meshes/m6r_0110/waist_link.STL" />
      </geometry>
      <material
        name="">
        <color
          rgba="0.894117647058823 0.894117647058823 0.894117647058823 1" />
      </material>
    </visual>
    <collision>
      <origin
        xyz="0 0 0"
        rpy="0 0 0" />
      <geometry>
        <mesh
          filename="package://m6r_description/meshes/m6r_0110/waist_link.STL" />
      </geometry>
    </collision>
  </link>
  <joint
    name="joint1"
    type="revolute">
    <origin
      xyz="0 0 0.175"
      rpy="0 0 0" />
    <parent
      link="base_link" />
    <child
      link="waist_link" />
    <axis
      xyz="0 0 1" />
    <limit
      lower="-3.14"
      upper="3.14"
      effort="50"
      velocity="100" />
  </joint>
  <link
    name="shoulder_link">
    <inertial>
      <origin
        xyz="-0.0393421032855981 0.0417793152023532 0.0773583929062565"
        rpy="0 0 0" />
      <mass
        value="5.239440252985" />
      <inertia
        ixx="0.0539250127743356"
        ixy="1.38922530733157E-06"
        ixz="0.0203431860572253"
        iyy="0.0726126815272468"
        iyz="-2.72845406496887E-06"
        izz="0.0242701394994817" />
    </inertial>
    <visual>
      <origin
        xyz="0 0 0"
        rpy="0 0 0" />
      <geometry>
        <mesh
          filename="package://m6r_description/meshes/m6r_0110/shoulder_link.STL" />
      </geometry>
      <material
        name="">
        <color
          rgba="0.752941176470588 0.752941176470588 0.752941176470588 1" />
      </material>
    </visual>
    <collision>
      <origin
        xyz="0 0 0"
        rpy="0 0 0" />
      <geometry>
        <mesh
          filename="package://m6r_description/meshes/m6r_0110/shoulder_link.STL" />
      </geometry>
    </collision>
  </link>
  <joint
    name="joint2"
    type="revolute">
    <origin
      xyz="0.1 0.094 0.175"
      rpy="0 0.47024 0" />
    <parent
      link="waist_link" />
    <child
      link="shoulder_link" />
    <axis
      xyz="0 1 0" />
    <limit
      lower="-3.14"
      upper="3.14"
      effort="50"
      velocity="100" />
  </joint>
  <link
    name="elbow_link">
    <inertial>
      <origin
        xyz="-0.0324458881612945 -0.0899423500054787 6.19472507663449E-05"
        rpy="0 0 0" />
      <mass
        value="3.1983360651658" />
      <inertia
        ixx="0.0112232922596549"
        ixy="-0.000413394805888793"
        ixz="-6.08808867039753E-08"
        iyy="0.0102793012206642"
        iyz="-6.82240237651006E-08"
        izz="0.0146558013438073" />
    </inertial>
    <visual>
      <origin
        xyz="0 0 0"
        rpy="0 0 0" />
      <geometry>
        <mesh
          filename="package://m6r_description/meshes/m6r_0110/elbow_link.STL" />
      </geometry>
      <material
        name="">
        <color
          rgba="0.894117647058823 0.894117647058823 0.894117647058823 1" />
      </material>
    </visual>
    <collision>
      <origin
        xyz="0 0 0"
        rpy="0 0 0" />
      <geometry>
        <mesh
          filename="package://m6r_description/meshes/m6r_0110/elbow_link.STL" />
      </geometry>
    </collision>
  </link>
  <joint
    name="joint3"
    type="revolute">
    <origin
      xyz="-0.12007 0 0.23624"
      rpy="3.1416 -1.1006 3.1416" />
    <parent
      link="shoulder_link" />
    <child
      link="elbow_link" />
    <axis
      xyz="0 1 0" />
    <limit
      lower="-3.14"
      upper="3.14"
      effort="50"
      velocity="100" />
  </joint>
  <link
    name="forearm_link">
    <inertial>
      <origin
        xyz="0.109668118306563 -4.13962910319617E-05 6.31873191234977E-05"
        rpy="0 0 0" />
      <mass
        value="3.39321721908934" />
      <inertia
        ixx="0.0140130697605679"
        ixy="9.48980902634125E-06"
        ixz="-9.8999024639953E-07"
        iyy="0.0190947215800425"
        iyz="-1.85475880373875E-07"
        izz="0.0280985723226197" />
    </inertial>
    <visual>
      <origin
        xyz="0 0 0"
        rpy="0 0 0" />
      <geometry>
        <mesh
          filename="package://m6r_description/meshes/m6r_0110/forearm_link.STL" />
      </geometry>
      <material
        name="">
        <color
          rgba="0.894117647058823 0.894117647058823 0.894117647058823 1" />
      </material>
    </visual>
    <collision>
      <origin
        xyz="0 0 0"
        rpy="0 0 0" />
      <geometry>
        <mesh
          filename="package://m6r_description/meshes/m6r_0110/forearm_link.STL" />
      </geometry>
    </collision>
  </link>
  <joint
    name="joint4"
    type="revolute">
    <origin
      xyz="0.045 -0.094 0"
      rpy="0 0 0" />
    <parent
      link="elbow_link" />
    <child
      link="forearm_link" />
    <axis
      xyz="1 0 0" />
    <limit
      lower="-3.14"
      upper="3.14"
      effort="50"
      velocity="100" />
  </joint>
  <link
    name="wriste_pitch">
    <inertial>
      <origin
        xyz="-0.0171303931049135 5.18595840840373E-15 6.24160410160612E-05"
        rpy="0 0 0" />
      <mass
        value="0.295781549289781" />
      <inertia
        ixx="0.000182023567605451"
        ixy="5.17679923091508E-20"
        ixz="3.12977259322246E-20"
        iyy="0.000310680621706772"
        iyz="-2.4319822037332E-20"
        izz="0.000308656048501104" />
    </inertial>
    <visual>
      <origin
        xyz="0 0 0"
        rpy="0 0 0" />
      <geometry>
        <mesh
          filename="package://m6r_description/meshes/m6r_0110/wriste_pitch.STL" />
      </geometry>
      <material
        name="">
        <color
          rgba="0.894117647058823 0.894117647058823 0.894117647058823 1" />
      </material>
    </visual>
    <collision>
      <origin
        xyz="0 0 0"
        rpy="0 0 0" />
      <geometry>
        <mesh
          filename="package://m6r_description/meshes/m6r_0110/wriste_pitch.STL" />
      </geometry>
    </collision>
  </link>
  <joint
    name="joint5"
    type="revolute">
    <origin
      xyz="0.225 0 0"
      rpy="0 0 0" />
    <parent
      link="forearm_link" />
    <child
      link="wriste_pitch" />
    <axis
      xyz="0 1 0" />
    <limit
      lower="-3.14"
      upper="3.14"
      effort="50"
      velocity="100" />
  </joint>
  <link
    name="wriste_roll">
    <inertial>
      <origin
        xyz="-0.14586 1.4401E-06 -0.0083042"
        rpy="0 0 0" />
      <mass
        value="0.24032" />
      <inertia
        ixx="0.00019091"
        ixy="6.6371E-09"
        ixz="-3.8831E-07"
        iyy="0.00015506"
        iyz="-2.8116E-09"
        izz="0.00019702" />
    </inertial>
    <visual>
      <origin
        xyz="0 0 0"
        rpy="0 0 0" />
      <geometry>
        <mesh
          filename="package://m6r_description/meshes/m6r_0110/wriste_roll.STL" />
      </geometry>
      <material
        name="">
        <color
          rgba="0.75294 0.75294 0.75294 1" />
      </material>
    </visual>
    <collision>
      <origin
        xyz="0 0 0"
        rpy="0 0 0" />
      <geometry>
        <mesh
          filename="package://m6r_description/meshes/m6r_0110/wriste_roll.STL" />
      </geometry>
    </collision>
  </link>
  <joint
    name="joint6"
    type="revolute">
    <origin
      xyz="0.208 0 6.2416E-05"
      rpy="3.1416 0 0" />
    <parent
      link="wriste_pitch" />
    <child
      link="wriste_roll" />
    <axis
      xyz="-1 0 0" />
    <limit
      lower="-3.14"
      upper="3.14"
      effort="50"
      velocity="100" />
  </joint>
</robot>